<?xml version="1.0"?>
<robot name="mobile_robot" xmlns:xacro="http://ros.org/wiki/xacro">

    <material name="blue">
	    <color rgba="0 0 0.8 1"/>
    </material>

    <material name="white">
	    <color rgba="1 1 1 1"/>
    </material>

    <material name="black">
	    <color rgba="0 0 0 1"/>
    </material>

    <material name="green">
        <color rgba="0.0 0.8 0.0 1.0"/>
    </material>

    <link name="base_link">
        <!--<visual>
          <geometry>
             <box size="0.24 0.24 0.001"/>
          </geometry>
          <material name="white"/>
          <origin rpy="0 0 0" xyz="0 0 0.0005"/>
          <material>
            <color rgba="0 0 0.8 1" />
          </material>
        </visual> -->
        <collision>
          <origin rpy="0 0 0" xyz="0 0 0"/>
          <geometry>
            <box size="0.22 0.22 0.001"/>
          </geometry>
        </collision>
    </link>

    <joint name="base_link_joint" type="fixed">
        <origin xyz="0 0 0.026" rpy="0 0 0" />
        <parent link="base_link" />
        <child link="base_plate" />
    </joint>

    <link name="base_plate">
      <visual>
        <origin xyz="0.092 0 0.055" rpy="0 0 1.5708" />
        <geometry>
          <mesh filename="package://STA_robot_explorateur_ros/stl/chassi.stl"/> 
        </geometry>
        <material name="blue"/>
      </visual>
      <collision>
        <origin xyz="0.092 0 0.055" rpy="0 0 1.5708" />
        <geometry>
          <mesh filename="package://STA_robot_explorateur_ros/stl/chassi.stl"/> 
        </geometry>
      </collision>
      <!---wheel-->
      <visual>
        <origin xyz="0 0.0725 0" rpy="0 -1.5708 0" />
        <geometry>
          <mesh filename="package://STA_robot_explorateur_ros/stl/wheel.stl"/>
        </geometry>
        <material name="white"/>
      </visual>
      <collision>
        <origin xyz="0 0.0725 0" rpy="0 -1.5708 0" />
        <geometry>
          <mesh filename="package://STA_robot_explorateur_ros/stl/wheel.stl"/>
        </geometry>
        <material name="white"/>
      </collision>

      <visual>
        <origin xyz="0 0.0725461 0" rpy="0 -1.5708 0" />
        <geometry>
          <mesh filename="package://STA_robot_explorateur_ros/stl/tire.stl"/>
        </geometry>
        <material name="black"/>
      </visual>
      <collision>
        <origin xyz="0 0.0725461 0" rpy="0 -1.5708 0" />
        <geometry>
          <mesh filename="package://STA_robot_explorateur_ros/stl/tire.stl"/>
        </geometry>
        <material name="black"/>
      </collision>

      <visual>
        <origin xyz="0 -0.0725 0" rpy="-3.14159 1.5708 0" />
        <geometry>
          <mesh filename="package://STA_robot_explorateur_ros/stl/wheel.stl"/>
        </geometry>
        <material name="white"/>
      </visual>
      <collision>
        <origin xyz="0 -0.0725 0" rpy="-3.14159 1.5708 0" />
        <geometry>
          <mesh filename="package://STA_robot_explorateur_ros/stl/wheel.stl"/>
        </geometry>
        <material name="white"/>
      </collision>

      <visual>
        <origin xyz="0 -0.0725461 0" rpy="-3.14159 1.5708 0" />
        <geometry>
          <mesh filename="package://STA_robot_explorateur_ros/stl/tire.stl"/>
        </geometry>
        <material name="black"/>
      </visual>
      <collision>
          <origin xyz="0 -0.0725461 0" rpy="-3.14159 1.5708 0" />
          <geometry>
          <mesh filename="package://STA_robot_explorateur_ros/stl/tire.stl"/>
          </geometry>
          <material name="black"/>
      </collision>
    </link>   
    

    <joint name="front_steer_joint" type="revolute">
        <origin xyz="0.192 0 0.013" rpy="0 0 1.5708" />
        <parent link="base_plate" />
        <child link="steering" />
        <axis xyz="0 0 1"/>
	      <limit effort="1" velocity="20" lower="-0.523599" upper="0.523599"/>
	      <joint_properties friction="0.0"/>
    </joint>

    <link name="steering">
      <visual>
        <origin xyz="0 0 -0.007" rpy="0 0 -1.5708" />
        <geometry>
          <mesh filename="package://STA_robot_explorateur_ros/stl/steering.stl"/>
        </geometry>
        <material name="blue"/>
      </visual>
      <collision>
        <origin xyz="0 0 -0.007" rpy="0 0 -1.5708" />
        <geometry>
          <mesh filename="package://STA_robot_explorateur_ros/stl/steering.stl"/>
        </geometry>
      </collision>
      <!---wheel-->
      <visual>
        <origin xyz="0 -0.1005  -0.013" rpy="0 -0.3744 0" />
        <geometry>
          <mesh filename="package://STA_robot_explorateur_ros/stl/wheel.stl"/>
        </geometry>
        <material name="white"/>
      </visual>
      <collision>
        <origin xyz="0 -0.1005 -0.013" rpy="0 -0.3744 0" />
        <geometry>
          <mesh filename="package://STA_robot_explorateur_ros/stl/wheel.stl"/>
        </geometry>
        <material name="white"/>
      </collision>
      <visual>
        <origin xyz="0 0.100454 -0.013" rpy="0 0 0" />
        <geometry>
          <mesh filename="package://STA_robot_explorateur_ros/stl/tire.stl"/>
        </geometry>
        <material name="black"/>
      </visual>
      <collision>
        <origin xyz="0 0.100454 -0.013" rpy="0 0 0" />
        <geometry>
          <mesh filename="package://STA_robot_explorateur_ros/stl/tire.stl"/>
        </geometry>
        <material name="black"/>
      </collision>
      <visual>
        <origin xyz="0 -0.100454 -0.013" rpy="0 -0.3744 0" />
        <geometry>
        <mesh filename="package://STA_robot_explorateur_ros/stl/tire.stl"/>
        </geometry>
        <material name="black">
        <color rgba="0.615686 0.811765 0.929412 1.0"/>
        </material>
      </visual>
      <collision>
        <origin xyz="0 -0.100454 -0.013" rpy="0 -0.3744 0" />
        <geometry>
          <mesh filename="package://STA_robot_explorateur_ros/stl/tire.stl"/>
        </geometry>
        <material name="black"/>
      </collision>
        <visual>
        <origin xyz="0 0.1005 -0.013" rpy="0 0 0" />
        <geometry>
          <mesh filename="package://STA_robot_explorateur_ros/stl/wheel.stl"/>
        </geometry>
        <material name="white"/>
      </visual>
      <collision>
        <origin xyz="0 0.1005 -0.013" rpy="0 0 0" />
        <geometry>
          <mesh filename="package://STA_robot_explorateur_ros/stl/wheel.stl"/>
        </geometry>
        <material name="white"/>
      </collision>

    </link>   
    
    <joint name="laser_joint" type="fixed">
        <origin xyz="0.0007 0 0.1375" rpy="0 0 0" />
        <parent link="base_plate" />
        <child link="laser_frame" />
        <axis xyz="0 0 1"/>
        <limit effort="1" velocity="20" />
        <joint_properties friction="0.0"/>
    </joint>

    <link name="laser_frame">
      <visual>
        <origin xyz="-0.00075 0 0.025" rpy="0 0 1.5708" />
        <geometry>
          <mesh filename="package://STA_robot_explorateur_ros/stl/lidar.stl"/>
        </geometry>
        <material name="black"/>
      </visual>
      <collision>
        <origin xyz="-0.00075 0 0.025" rpy="0 0 0" />
        <geometry>
          <mesh filename="package://STA_robot_explorateur_ros/stl/lidar.stl"/>
        </geometry>
      </collision>
    </link>  
    
</robot>
